[2024-02-05T19:40:22.360+0000] {taskinstance.py:1956} INFO - Dependencies all met for dep_context=non-requeueable deps ti=<TaskInstance: dag_crypto_ETL.coinmarketcap_fetch_data manual__2024-02-05T19:40:20.604768+00:00 [queued]>
[2024-02-05T19:40:22.376+0000] {taskinstance.py:1956} INFO - Dependencies all met for dep_context=requeueable deps ti=<TaskInstance: dag_crypto_ETL.coinmarketcap_fetch_data manual__2024-02-05T19:40:20.604768+00:00 [queued]>
[2024-02-05T19:40:22.378+0000] {taskinstance.py:2170} INFO - Starting attempt 1 of 1
[2024-02-05T19:40:22.399+0000] {taskinstance.py:2191} INFO - Executing <Task(PythonOperator): coinmarketcap_fetch_data> on 2024-02-05 19:40:20.604768+00:00
[2024-02-05T19:40:22.406+0000] {standard_task_runner.py:60} INFO - Started process 4582 to run task
[2024-02-05T19:40:22.412+0000] {standard_task_runner.py:87} INFO - Running: ['***', 'tasks', 'run', 'dag_crypto_ETL', 'coinmarketcap_fetch_data', 'manual__2024-02-05T19:40:20.604768+00:00', '--job-id', '26', '--raw', '--subdir', 'DAGS_FOLDER/dag_v1.py', '--cfg-path', '/tmp/tmp9avcgkcs']
[2024-02-05T19:40:22.416+0000] {standard_task_runner.py:88} INFO - Job 26: Subtask coinmarketcap_fetch_data
[2024-02-05T19:40:22.497+0000] {task_command.py:423} INFO - Running <TaskInstance: dag_crypto_ETL.coinmarketcap_fetch_data manual__2024-02-05T19:40:20.604768+00:00 [running]> on host 0fd5da028511
[2024-02-05T19:40:22.841+0000] {taskinstance.py:2480} INFO - Exporting env vars: AIRFLOW_CTX_DAG_OWNER='***' AIRFLOW_CTX_DAG_ID='dag_crypto_ETL' AIRFLOW_CTX_TASK_ID='coinmarketcap_fetch_data' AIRFLOW_CTX_EXECUTION_DATE='2024-02-05T19:40:20.604768+00:00' AIRFLOW_CTX_TRY_NUMBER='1' AIRFLOW_CTX_DAG_RUN_ID='manual__2024-02-05T19:40:20.604768+00:00'
[2024-02-05T19:40:23.435+0000] {taskinstance.py:2698} ERROR - Task failed with exception
Traceback (most recent call last):
  File "/home/airflow/.local/lib/python3.8/site-packages/airflow/models/taskinstance.py", line 433, in _execute_task
    result = execute_callable(context=context, **execute_callable_kwargs)
  File "/home/airflow/.local/lib/python3.8/site-packages/airflow/operators/python.py", line 199, in execute
    return_value = self.execute_callable()
  File "/home/airflow/.local/lib/python3.8/site-packages/airflow/operators/python.py", line 216, in execute_callable
    return self.python_callable(*self.op_args, **self.op_kwargs)
  File "/opt/airflow/dags/coinmarketcap_fetch_data.py", line 28, in fetch_data
    with open(saved_file_path, 'w+') as file:
FileNotFoundError: [Errno 2] No such file or directory: 'api_data/2024-02-05T19:40:23.473Z.json'
[2024-02-05T19:40:23.454+0000] {taskinstance.py:1138} INFO - Marking task as FAILED. dag_id=dag_crypto_ETL, task_id=coinmarketcap_fetch_data, execution_date=20240205T194020, start_date=20240205T194022, end_date=20240205T194023
[2024-02-05T19:40:23.475+0000] {standard_task_runner.py:107} ERROR - Failed to execute job 26 for task coinmarketcap_fetch_data ([Errno 2] No such file or directory: 'api_data/2024-02-05T19:40:23.473Z.json'; 4582)
[2024-02-05T19:40:23.517+0000] {local_task_job_runner.py:234} INFO - Task exited with return code 1
[2024-02-05T19:40:23.546+0000] {taskinstance.py:3280} INFO - 0 downstream tasks scheduled from follow-on schedule check
